2021-10-25 02:37:40,413 INFO    MainThread:7160 [wandb_setup.py:_flush():71] setting env: {}
2021-10-25 02:37:40,413 INFO    MainThread:7160 [wandb_setup.py:_flush():71] setting login settings: {}
2021-10-25 02:37:40,413 INFO    MainThread:7160 [wandb_init.py:_log_setup():357] Logging user logs to /opt/ml/segmentation/mmsegmentation/configs/_base_/models/CSwin/wandb/run-20211025_023740-2817n3gi/logs/debug.log
2021-10-25 02:37:40,413 INFO    MainThread:7160 [wandb_init.py:_log_setup():358] Logging internal logs to /opt/ml/segmentation/mmsegmentation/configs/_base_/models/CSwin/wandb/run-20211025_023740-2817n3gi/logs/debug-internal.log
2021-10-25 02:37:40,413 INFO    MainThread:7160 [wandb_init.py:init():390] calling init triggers
2021-10-25 02:37:40,413 INFO    MainThread:7160 [wandb_init.py:init():397] wandb.init called with sweep_config: {}
config: {}
2021-10-25 02:37:40,413 INFO    MainThread:7160 [wandb_init.py:init():435] starting backend
2021-10-25 02:37:40,414 INFO    MainThread:7160 [backend.py:_multiprocessing_setup():96] multiprocessing start_methods=fork,spawn,forkserver, using: spawn
2021-10-25 02:37:40,442 INFO    MainThread:7160 [backend.py:ensure_launched():198] starting backend process...
2021-10-25 02:37:40,473 INFO    MainThread:7160 [backend.py:ensure_launched():204] started backend process with pid: 7285
2021-10-25 02:37:40,475 INFO    MainThread:7160 [wandb_init.py:init():444] backend started and connected
2021-10-25 02:37:40,477 INFO    MainThread:7160 [wandb_init.py:init():503] updated telemetry
2021-10-25 02:37:40,534 INFO    MainThread:7160 [wandb_init.py:init():533] communicating current version
2021-10-25 02:37:44,279 INFO    MainThread:7160 [wandb_init.py:init():538] got version response 
2021-10-25 02:37:44,279 INFO    MainThread:7160 [wandb_init.py:init():548] communicating run to backend with 30 second timeout
2021-10-25 02:37:44,506 INFO    MainThread:7160 [wandb_init.py:init():576] starting run threads in backend
2021-10-25 02:37:48,484 INFO    MainThread:7160 [wandb_run.py:_console_start():1693] atexit reg
2021-10-25 02:37:48,485 INFO    MainThread:7160 [wandb_run.py:_redirect():1567] redirect: SettingsConsole.REDIRECT
2021-10-25 02:37:48,485 INFO    MainThread:7160 [wandb_run.py:_redirect():1572] Redirecting console.
2021-10-25 02:37:48,487 INFO    MainThread:7160 [wandb_run.py:_redirect():1628] Redirects installed.
2021-10-25 02:37:48,487 INFO    MainThread:7160 [wandb_init.py:init():603] run started, returning control to user process
2021-10-25 02:38:09,099 ERROR   Thread-1  :7160 [retry.py:__call__():126] Retry attempt failed:
Traceback (most recent call last):
  File "/opt/conda/envs/psc/lib/python3.7/site-packages/urllib3/connection.py", line 175, in _new_conn
    (self._dns_host, self.port), self.timeout, **extra_kw
  File "/opt/conda/envs/psc/lib/python3.7/site-packages/urllib3/util/connection.py", line 96, in create_connection
    raise err
  File "/opt/conda/envs/psc/lib/python3.7/site-packages/urllib3/util/connection.py", line 86, in create_connection
    sock.connect(sa)
socket.timeout: timed out

During handling of the above exception, another exception occurred:

Traceback (most recent call last):
  File "/opt/conda/envs/psc/lib/python3.7/site-packages/urllib3/connectionpool.py", line 706, in urlopen
    chunked=chunked,
  File "/opt/conda/envs/psc/lib/python3.7/site-packages/urllib3/connectionpool.py", line 382, in _make_request
    self._validate_conn(conn)
  File "/opt/conda/envs/psc/lib/python3.7/site-packages/urllib3/connectionpool.py", line 1010, in _validate_conn
    conn.connect()
  File "/opt/conda/envs/psc/lib/python3.7/site-packages/urllib3/connection.py", line 358, in connect
    conn = self._new_conn()
  File "/opt/conda/envs/psc/lib/python3.7/site-packages/urllib3/connection.py", line 182, in _new_conn
    % (self.host, self.timeout),
urllib3.exceptions.ConnectTimeoutError: (<urllib3.connection.HTTPSConnection object at 0x7fef4ab5dcd0>, 'Connection to api.wandb.ai timed out. (connect timeout=10)')

During handling of the above exception, another exception occurred:

Traceback (most recent call last):
  File "/opt/conda/envs/psc/lib/python3.7/site-packages/requests/adapters.py", line 449, in send
    timeout=timeout
  File "/opt/conda/envs/psc/lib/python3.7/site-packages/urllib3/connectionpool.py", line 756, in urlopen
    method, url, error=e, _pool=self, _stacktrace=sys.exc_info()[2]
  File "/opt/conda/envs/psc/lib/python3.7/site-packages/urllib3/util/retry.py", line 574, in increment
    raise MaxRetryError(_pool, url, error or ResponseError(cause))
urllib3.exceptions.MaxRetryError: HTTPSConnectionPool(host='api.wandb.ai', port=443): Max retries exceeded with url: /graphql (Caused by ConnectTimeoutError(<urllib3.connection.HTTPSConnection object at 0x7fef4ab5dcd0>, 'Connection to api.wandb.ai timed out. (connect timeout=10)'))

During handling of the above exception, another exception occurred:

Traceback (most recent call last):
  File "/opt/conda/envs/psc/lib/python3.7/site-packages/wandb/sdk/lib/retry.py", line 102, in __call__
    result = self._call_fn(*args, **kwargs)
  File "/opt/conda/envs/psc/lib/python3.7/site-packages/wandb/sdk/internal/internal_api.py", line 141, in execute
    return self.client.execute(*args, **kwargs)
  File "/opt/conda/envs/psc/lib/python3.7/site-packages/wandb/vendor/gql-0.2.0/gql/client.py", line 52, in execute
    result = self._get_result(document, *args, **kwargs)
  File "/opt/conda/envs/psc/lib/python3.7/site-packages/wandb/vendor/gql-0.2.0/gql/client.py", line 60, in _get_result
    return self.transport.execute(document, *args, **kwargs)
  File "/opt/conda/envs/psc/lib/python3.7/site-packages/wandb/vendor/gql-0.2.0/gql/transport/requests.py", line 38, in execute
    request = requests.post(self.url, **post_args)
  File "/opt/conda/envs/psc/lib/python3.7/site-packages/requests/api.py", line 117, in post
    return request('post', url, data=data, json=json, **kwargs)
  File "/opt/conda/envs/psc/lib/python3.7/site-packages/requests/api.py", line 61, in request
    return session.request(method=method, url=url, **kwargs)
  File "/opt/conda/envs/psc/lib/python3.7/site-packages/requests/sessions.py", line 542, in request
    resp = self.send(prep, **send_kwargs)
  File "/opt/conda/envs/psc/lib/python3.7/site-packages/requests/sessions.py", line 655, in send
    r = adapter.send(request, **kwargs)
  File "/opt/conda/envs/psc/lib/python3.7/site-packages/requests/adapters.py", line 504, in send
    raise ConnectTimeout(e, request=request)
requests.exceptions.ConnectTimeout: HTTPSConnectionPool(host='api.wandb.ai', port=443): Max retries exceeded with url: /graphql (Caused by ConnectTimeoutError(<urllib3.connection.HTTPSConnection object at 0x7fef4ab5dcd0>, 'Connection to api.wandb.ai timed out. (connect timeout=10)'))
2021-10-25 05:00:05,374 INFO    MainThread:7160 [wandb_run.py:finish():1347] finishing run ark10806/segm_augs/2817n3gi
2021-10-25 05:00:05,375 INFO    MainThread:7160 [wandb_run.py:_atexit_cleanup():1663] got exitcode: 0
2021-10-25 05:00:05,375 INFO    MainThread:7160 [wandb_run.py:_restore():1635] restore
2021-10-25 05:00:07,410 INFO    MainThread:7160 [wandb_run.py:_wait_for_finish():1793] got exit ret: file_counts {
  wandb_count: 1
}
pusher_stats {
  uploaded_bytes: 898
  total_bytes: 898
}

2021-10-25 05:00:07,651 INFO    MainThread:7160 [wandb_run.py:_wait_for_finish():1793] got exit ret: file_counts {
  wandb_count: 1
}
pusher_stats {
  uploaded_bytes: 898
  total_bytes: 898
}

2021-10-25 05:00:08,648 INFO    MainThread:7160 [wandb_run.py:_wait_for_finish():1793] got exit ret: file_counts {
  wandb_count: 4
}
pusher_stats {
  uploaded_bytes: 898
  total_bytes: 115520
}

2021-10-25 05:00:08,750 INFO    MainThread:7160 [wandb_run.py:_wait_for_finish():1793] got exit ret: file_counts {
  wandb_count: 6
}
pusher_stats {
  uploaded_bytes: 898
  total_bytes: 121270
}

2021-10-25 05:00:08,851 INFO    MainThread:7160 [wandb_run.py:_wait_for_finish():1793] got exit ret: file_counts {
  wandb_count: 6
}
pusher_stats {
  uploaded_bytes: 898
  total_bytes: 121270
}

2021-10-25 05:00:08,952 INFO    MainThread:7160 [wandb_run.py:_wait_for_finish():1793] got exit ret: file_counts {
  wandb_count: 6
}
pusher_stats {
  uploaded_bytes: 121270
  total_bytes: 121270
}

2021-10-25 05:00:09,053 INFO    MainThread:7160 [wandb_run.py:_wait_for_finish():1793] got exit ret: file_counts {
  wandb_count: 6
}
pusher_stats {
  uploaded_bytes: 121270
  total_bytes: 121270
}

2021-10-25 05:00:09,154 INFO    MainThread:7160 [wandb_run.py:_wait_for_finish():1793] got exit ret: file_counts {
  wandb_count: 6
}
pusher_stats {
  uploaded_bytes: 121270
  total_bytes: 121270
}

2021-10-25 05:00:09,256 INFO    MainThread:7160 [wandb_run.py:_wait_for_finish():1793] got exit ret: file_counts {
  wandb_count: 6
}
pusher_stats {
  uploaded_bytes: 121270
  total_bytes: 121270
}

2021-10-25 05:00:09,357 INFO    MainThread:7160 [wandb_run.py:_wait_for_finish():1793] got exit ret: file_counts {
  wandb_count: 6
}
pusher_stats {
  uploaded_bytes: 121270
  total_bytes: 121270
}

2021-10-25 05:00:09,821 INFO    MainThread:7160 [wandb_run.py:_wait_for_finish():1793] got exit ret: file_counts {
  wandb_count: 6
}
pusher_stats {
  uploaded_bytes: 121270
  total_bytes: 121270
}

2021-10-25 05:00:10,283 INFO    MainThread:7160 [wandb_run.py:_wait_for_finish():1793] got exit ret: done: true
exit_result {
}
file_counts {
  wandb_count: 6
}
pusher_stats {
  uploaded_bytes: 121270
  total_bytes: 121270
}
local_info {
}

2021-10-25 05:00:11,413 INFO    MainThread:7160 [wandb_run.py:_append_history():2011] rendering history
2021-10-25 05:00:11,415 INFO    MainThread:7160 [wandb_run.py:_append_summary():1966] rendering summary
2021-10-25 05:00:11,415 INFO    MainThread:7160 [wandb_run.py:_append_files():2061] logging synced files
